Workbook

Sheet README
A1: Insurance Comparison Platform - Reference Data Workbook
A3: Purpose | B3: Structured reference data from research through October 1, 2026 (California auto and home; Texas, Florida, New York, Illinois, Pennsylvania, Georgia, North Carolina and Virginia auto; Texas, Florida, New York, Illinois, Pennsylvania, Georgia, North Carolina and Virginia home verified from primary sources; California home credit-use rules still open) for the U.S. auto and home insurance education/comparison project.
A4: As-of date | B4: 46296
A5: Important | B5: This is reference data, not insurer quotes or advice. Most entries come from secondary sources and must be checked against state DOI, statute or carrier filings before use on a live site.
A6: How to edit | B6: Edit any cell in the data tabs. Add new rows at the bottom, keep the standard columns filled, and set Verification Status from the dropdown.
A7: Standard columns | B7: Every data tab ends with: Source, Source URL, Date Collected, Geographic Scope, Data Type, Verification Status, Last Updated, Notes.
A9: Verification Status legend
A10: Primary source | B10: From a regulator, government body or the carrier's own published terms. Still confirm it is current.
A11: Secondary - unverified | B11: From a comparison site, publisher or blog. Treat as a lead to verify, not a fact to publish.
A12: Conflicting | B12: Sources disagree. See Conflicts Log.
A13: Not researched | B13: Placeholder row; nothing researched yet.
A15: Status count by tab (live formulas)
A16: Tab | B16: Primary source | C16: Secondary - unverified | D16: Conflicting | E16: Not researched | F16: Total rows
A17: State Min Limits | B17: =COUNTIF('State Min Limits'!$N$2:$N$500,"Primary source") | C17: =COUNTIF('State Min Limits'!$N$2:$N$500,"Secondary - unverified") | D17: =COUNTIF('State Min Limits'!$N$2:$N$500,"Conflicting") | E17: =COUNTIF('State Min Limits'!$N$2:$N$500,"Not researched") | F17: =SUM(B17:E17)
A18: Rating Factors | B18: =COUNTIF('Rating Factors'!$L$2:$L$500,"Primary source") | C18: =COUNTIF('Rating Factors'!$L$2:$L$500,"Secondary - unverified") | D18: =COUNTIF('Rating Factors'!$L$2:$L$500,"Conflicting") | E18: =COUNTIF('Rating Factors'!$L$2:$L$500,"Not researched") | F18: =SUM(B18:E18)
A19: Discounts | B19: =COUNTIF(Discounts!$K$2:$K$500,"Primary source") | C19: =COUNTIF(Discounts!$K$2:$K$500,"Secondary - unverified") | D19: =COUNTIF(Discounts!$K$2:$K$500,"Conflicting") | E19: =COUNTIF(Discounts!$K$2:$K$500,"Not researched") | F19: =SUM(B19:E19)
A20: Telematics | B20: =COUNTIF(Telematics!$M$2:$M$500,"Primary source") | C20: =COUNTIF(Telematics!$M$2:$M$500,"Secondary - unverified") | D20: =COUNTIF(Telematics!$M$2:$M$500,"Conflicting") | E20: =COUNTIF(Telematics!$M$2:$M$500,"Not researched") | F20: =SUM(B20:E20)
A21: Coverage Details | B21: =COUNTIF('Coverage Details'!$J$2:$J$500,"Primary source") | C21: =COUNTIF('Coverage Details'!$J$2:$J$500,"Secondary - unverified") | D21: =COUNTIF('Coverage Details'!$J$2:$J$500,"Conflicting") | E21: =COUNTIF('Coverage Details'!$J$2:$J$500,"Not researched") | F21: =SUM(B21:E21)
A22: Price Benchmarks | B22: =COUNTIF('Price Benchmarks'!$K$2:$K$500,"Primary source") | C22: =COUNTIF('Price Benchmarks'!$K$2:$K$500,"Secondary - unverified") | D22: =COUNTIF('Price Benchmarks'!$K$2:$K$500,"Conflicting") | E22: =COUNTIF('Price Benchmarks'!$K$2:$K$500,"Not researched") | F22: =SUM(B22:E22)
A23: Regulatory Watch | B23: =COUNTIF('Regulatory Watch'!$J$2:$J$500,"Primary source") | C23: =COUNTIF('Regulatory Watch'!$J$2:$J$500,"Secondary - unverified") | D23: =COUNTIF('Regulatory Watch'!$J$2:$J$500,"Conflicting") | E23: =COUNTIF('Regulatory Watch'!$J$2:$J$500,"Not researched") | F23: =SUM(B23:E23)
A24: CA Auto Verified | B24: =COUNTIF('CA Auto Verified'!$J$2:$J$500,"Primary source") | C24: =COUNTIF('CA Auto Verified'!$J$2:$J$500,"Secondary - unverified") | D24: =COUNTIF('CA Auto Verified'!$J$2:$J$500,"Conflicting") | E24: =COUNTIF('CA Auto Verified'!$J$2:$J$500,"Not researched") | F24: =SUM(B24:E24)
A25: CA Home Verified | B25: =COUNTIF('CA Home Verified'!$J$2:$J$500,"Primary source") | C25: =COUNTIF('CA Home Verified'!$J$2:$J$500,"Secondary - unverified") | D25: =COUNTIF('CA Home Verified'!$J$2:$J$500,"Conflicting") | E25: =COUNTIF('CA Home Verified'!$J$2:$J$500,"Not researched") | F25: =SUM(B25:E25)
A26: TX Auto Verified | B26: =COUNTIF('TX Auto Verified'!$J$2:$J$500,"Primary source") | C26: =COUNTIF('TX Auto Verified'!$J$2:$J$500,"Secondary - unverified") | D26: =COUNTIF('TX Auto Verified'!$J$2:$J$500,"Conflicting") | E26: =COUNTIF('TX Auto Verified'!$J$2:$J$500,"Not researched") | F26: =SUM(B26:E26)
A27: FL Auto Verified | B27: =COUNTIF('FL Auto Verified'!$J$2:$J$500,"Primary source") | C27: =COUNTIF('FL Auto Verified'!$J$2:$J$500,"Secondary - unverified") | D27: =COUNTIF('FL Auto Verified'!$J$2:$J$500,"Conflicting") | E27: =COUNTIF('FL Auto Verified'!$J$2:$J$500,"Not researched") | F27: =SUM(B27:E27)
A28: NY Auto Verified | B28: =COUNTIF('NY Auto Verified'!$J$2:$J$500,"Primary source") | C28: =COUNTIF('NY Auto Verified'!$J$2:$J$500,"Secondary - unverified") | D28: =COUNTIF('NY Auto Verified'!$J$2:$J$500,"Conflicting") | E28: =COUNTIF('NY Auto Verified'!$J$2:$J$500,"Not researched") | F28: =SUM(B28:E28)
A29: TX Home Verified | B29: =COUNTIF('TX Home Verified'!$J$2:$J$500,"Primary source") | C29: =COUNTIF('TX Home Verified'!$J$2:$J$500,"Secondary - unverified") | D29: =COUNTIF('TX Home Verified'!$J$2:$J$500,"Conflicting") | E29: =COUNTIF('TX Home Verified'!$J$2:$J$500,"Not researched") | F29: =SUM(B29:E29)
A30: FL Home Verified | B30: =COUNTIF('FL Home Verified'!$J$2:$J$500,"Primary source") | C30: =COUNTIF('FL Home Verified'!$J$2:$J$500,"Secondary - unverified") | D30: =COUNTIF('FL Home Verified'!$J$2:$J$500,"Conflicting") | E30: =COUNTIF('FL Home Verified'!$J$2:$J$500,"Not researched") | F30: =SUM(B30:E30)
A31: NY Home Verified | B31: =COUNTIF('NY Home Verified'!$J$2:$J$500,"Primary source") | C31: =COUNTIF('NY Home Verified'!$J$2:$J$500,"Secondary - unverified") | D31: =COUNTIF('NY Home Verified'!$J$2:$J$500,"Conflicting") | E31: =COUNTIF('NY Home Verified'!$J$2:$J$500,"Not researched") | F31: =SUM(B31:E31)
A32: IL Auto Verified | B32: =COUNTIF('IL Auto Verified'!$J$2:$J$500,"Primary source") | C32: =COUNTIF('IL Auto Verified'!$J$2:$J$500,"Secondary - unverified") | D32: =COUNTIF('IL Auto Verified'!$J$2:$J$500,"Conflicting") | E32: =COUNTIF('IL Auto Verified'!$J$2:$J$500,"Not researched") | F32: =SUM(B32:E32)
A33: IL Home Verified | B33: =COUNTIF('IL Home Verified'!$J$2:$J$500,"Primary source") | C33: =COUNTIF('IL Home Verified'!$J$2:$J$500,"Secondary - unverified") | D33: =COUNTIF('IL Home Verified'!$J$2:$J$500,"Conflicting") | E33: =COUNTIF('IL Home Verified'!$J$2:$J$500,"Not researched") | F33: =SUM(B33:E33)
A34: PA Auto Verified | B34: =COUNTIF('PA Auto Verified'!$J$2:$J$500,"Primary source") | C34: =COUNTIF('PA Auto Verified'!$J$2:$J$500,"Secondary - unverified") | D34: =COUNTIF('PA Auto Verified'!$J$2:$J$500,"Conflicting") | E34: =COUNTIF('PA Auto Verified'!$J$2:$J$500,"Not researched") | F34: =SUM(B34:E34)
A35: PA Home Verified | B35: =COUNTIF('PA Home Verified'!$J$2:$J$500,"Primary source") | C35: =COUNTIF('PA Home Verified'!$J$2:$J$500,"Secondary - unverified") | D35: =COUNTIF('PA Home Verified'!$J$2:$J$500,"Conflicting") | E35: =COUNTIF('PA Home Verified'!$J$2:$J$500,"Not researched") | F35: =SUM(B35:E35)
A36: GA Auto Verified | B36: =COUNTIF('GA Auto Verified'!$J$2:$J$500,"Primary source") | C36: =COUNTIF('GA Auto Verified'!$J$2:$J$500,"Secondary - unverified") | D36: =COUNTIF('GA Auto Verified'!$J$2:$J$500,"Conflicting") | E36: =COUNTIF('GA Auto Verified'!$J$2:$J$500,"Not researched") | F36: =SUM(B36:E36)
A37: GA Home Verified | B37: =COUNTIF('GA Home Verified'!$J$2:$J$500,"Primary source") | C37: =COUNTIF('GA Home Verified'!$J$2:$J$500,"Secondary - unverified") | D37: =COUNTIF('GA Home Verified'!$J$2:$J$500,"Conflicting") | E37: =COUNTIF('GA Home Verified'!$J$2:$J$500,"Not researched") | F37: =SUM(B37:E37)
A38: NC Auto Verified | B38: =COUNTIF('NC Auto Verified'!$J$2:$J$500,"Primary source") | C38: =COUNTIF('NC Auto Verified'!$J$2:$J$500,"Secondary - unverified") | D38: =COUNTIF('NC Auto Verified'!$J$2:$J$500,"Conflicting") | E38: =COUNTIF('NC Auto Verified'!$J$2:$J$500,"Not researched") | F38: =SUM(B38:E38)
A39: NC Home Verified | B39: =COUNTIF('NC Home Verified'!$J$2:$J$500,"Primary source") | C39: =COUNTIF('NC Home Verified'!$J$2:$J$500,"Secondary - unverified") | D39: =COUNTIF('NC Home Verified'!$J$2:$J$500,"Conflicting") | E39: =COUNTIF('NC Home Verified'!$J$2:$J$500,"Not researched") | F39: =SUM(B39:E39)
A40: VA Auto Verified | B40: =COUNTIF('VA Auto Verified'!$J$2:$J$500,"Primary source") | C40: =COUNTIF('VA Auto Verified'!$J$2:$J$500,"Secondary - unverified") | D40: =COUNTIF('VA Auto Verified'!$J$2:$J$500,"Conflicting") | E40: =COUNTIF('VA Auto Verified'!$J$2:$J$500,"Not researched") | F40: =SUM(B40:E40)
A41: VA Home Verified | B41: =COUNTIF('VA Home Verified'!$J$2:$J$500,"Primary source") | C41: =COUNTIF('VA Home Verified'!$J$2:$J$500,"Secondary - unverified") | D41: =COUNTIF('VA Home Verified'!$J$2:$J$500,"Conflicting") | E41: =COUNTIF('VA Home Verified'!$J$2:$J$500,"Not researched") | F41: =SUM(B41:E41)
A42: All tabs | B42: =SUM(B17:B41) | C42: =SUM(C17:C41) | D42: =SUM(D17:D41) | E42: =SUM(E17:E41) | F42: =SUM(F17:F41)
A43: TX Home Verified | B43: Texas home facts from TDI, TWIA and secondary sources.
...

Sheet CA Auto Verified
A1: Topic | B1: Fact | C1: Value | D1: Legal Citation | E1: Source | F1: Source URL | G1: Date Collected | H1: Geographic Scope | I1: Data Type | J1: Verification Status | K1: Last Updated | L1: Notes
A2: Minimum liability | B2: Bodily injury per person | C2: $30,000 | D2: Ins. Code 11580.1(b) (per DMV) | E2: CA DMV - Auto Insurance Requirements (modified Jul 10, 2025) | F2: https://www.dmv.ca.gov/portal/vehicle-registration/insurance-requirements/ | G2: 46295 | H2: California | I2: Regulator-published | J2: Primary source | K2: 46295 | L2: CDI Form 101 states the same limits.
A3: Minimum liability | B3: Bodily injury per accident | C3: $60,000 | D3: Ins. Code 11580.1(b) (per DMV) | E3: CA DMV - Auto Insurance Requirements (modified Jul 10, 2025) | F3: https://www.dmv.ca.gov/portal/vehicle-registration/insurance-requirements/ | G3: 46295 | H3: California | I3: Regulator-published | J3: Primary source | K3: 46295
A4: Minimum liability | B4: Property damage | C4: $15,000 | D4: Ins. Code 11580.1(b) (per DMV) | E4: CA DMV - Auto Insurance Requirements (modified Jul 10, 2025) | F4: https://www.dmv.ca.gov/portal/vehicle-registration/insurance-requirements/ | G4: 46295 | H4: California | I4: Regulator-published | J4: Primary source | K4: 46295
A5: Minimum liability | B5: Timing of increase | C5: Increased limits begin 2025 under SB 1107 | D5: SB 1107 (2022) | E5: CA Dept of Insurance - Low Cost Auto consumer alert (Jul 23, 2024) | F5: https://www.insurance.ca.gov/0400-news/0102-alerts/2024/California-s-Low-Cost-Auto-Insurance.cfm | G5: 46295 | H5: California | I5: Regulator-published | J5: Primary source | K5: 46295 | L5: CDI alert says liability limits increase beginning 2025.
A6: Minimum liability | B6: Existing policies adjust at renewal | C6: Policies renew at the new limits | D6: Per law-firm summary of CDI position | E6: CarInsurance.com - Minimum liability by state (Apr 2026) | F6: https://www.carinsurance.com/Articles/minimum-liability-car-insurance-requirements-by-state.aspx | G6: 46295 | H6: California | I6: Reference data (secondary source) | J6: Secondary - unverified | K6: 46295 | L6: Verify with CDI.
A7: Minimum liability | B7: Scheduled second increase | C7: On Jan 1, 2035 minimums rise by $20,000 (per person), $40,000 (per accident) and $10,000 (property damage): 50/100/25 | D7: SB 1107 (2022) text | E7: SB 1107 (2021-22) enrolled bill text - Vehicles: insurance (leginfo) | F7: https://leginfo.legislature.ca.gov/faces/billNavClient.xhtml?bill_id=202120220SB1107 | G7: 46295 | H7: California | I7: Statute / regulation text | J7: Primary source | K7: 46295 | L7: Confirmed in the bill text on leginfo. Agency and law-firm sites report the same 50/100/25.
A8: Financial responsibility | B8: Alternatives to insurance (DMV) | C8: Cash deposit $75,000; surety bond $75,000; DMV self-insurance certificate | D8: DMV page (Jul 2025); SB 1107 | E8: CA DMV - Auto Insurance Requirements (modified Jul 10, 2025) | F8: https://www.dmv.ca.gov/portal/vehicle-registration/insurance-requirements/ | G8: 46295 | H8: California | I8: Regulator-published | J8: Primary source | K8: 46295 | L8: Resolved: SB 1107 raised the deposit to $75,000 (and by $50,000 more on Jan 1, 2035). CDI Form 101's $35,000 figure is out of date.
A9: Financial responsibility | B9: Collision/comprehensive | C9: Do not satisfy financial responsibility | D9: DMV page | E9: CA DMV - Auto Insurance Requirements (modified Jul 10, 2025) | F9: https://www.dmv.ca.gov/portal/vehicle-registration/insurance-requirements/ | G9: 46295 | H9: California | I9: Regulator-published | J9: Primary source | K9: 46295 | L9: Liability is the only required coverage.
A10: Financial responsibility | B10: When proof must be shown | C10: On request by law enforcement, at registration renewal, after a collision | D10: DMV page | E10: CA DMV - Auto Insurance Requirements (modified Jul 10, 2025) | F10: https://www.dmv.ca.gov/portal/vehicle-registration/insurance-requirements/ | G10: 46295 | H10: California | I10: Regulator-published | J10: Primary source | K10: 46295 | L10: Registration is suspended if DMV does not receive proof.
A11: Financial responsibility | B11: Insurers report to DMV | C11: Electronic reporting required | D11: Veh. Code 16058 (per DMV) | E11: CA DMV - Auto Insurance Requirements (modified Jul 10, 2025) | F11: https://www.dmv.ca.gov/portal/vehicle-registration/insurance-requirements/ | G11: 46295 | H11: California | I11: Regulator-published | J11: Primary source | K11: 46295
A12: Other coverages | B12: Uninsured/underinsured motorist | C12: Must be offered; can be declined by signed waiver; UMBI limits equal liability limits | D12: CDI Form 101 | E12: CA Dept of Insurance - Introduction to Auto Insurance (Form 101, rev. Feb 5, 2025) | F12: https://www.insurance.ca.gov/01-consumers/105-type/95-guides/01-auto/auto101.cfm | G12: 46295 | H12: California | I12: Regulator-published | J12: Primary source | K12: 46295
A13: Other coverages | B13: UM property damage limit | C13: $3,500 (only if uninsured driver identified) | D13: CDI Form 101 | E13: CA Dept of Insurance - Introduction to Auto Insurance (Form 101, rev. Feb 5, 2025) | F13: https://www.insurance.ca.gov/01-consumers/105-type/95-guides/01-auto/auto101.cfm | G13: 46295 | H13: California | I13: Regulator-published | J13: Primary source | K13: 46295
A14: Other coverages | B14: Medical payments | C14: Optional; minimum limit you can buy is $1,000 per person | D14: CDI Form 101 | E14: CA Dept of Insurance - Introduction to Auto Insurance (Form 101, rev. Feb 5, 2025) | F14: https://www.insurance.ca.gov/01-consumers/105-type/95-guides/01-auto/auto101.cfm | G14: 46295 | H14: California | I14: Regulator-published | J14: Primary source | K14: 46295
A15: Fault and claims | B15: Fault rule | C15: Comparative negligence | D15: CDI Form 101 | E15: CA Dept of Insurance - Introduction to Auto Insurance (Form 101, rev. Feb 5, 2025) | F15: https://www.insurance.ca.gov/01-consumers/105-type/95-guides/01-auto/auto101.cfm | G15: 46295 | H15: California | I15: Regulator-published | J15: Primary source | K15: 46295
A16: Fault and claims | B16: Surcharge after an accident | C16: None if not at fault; can apply at renewal if at least 51% at fault | D16: CDI Form 101 | E16: CA Dept of Insurance - Introduction to Auto Insurance (Form 101, rev. Feb 5, 2025) | F16: https://www.insurance.ca.gov/01-consumers/105-type/95-guides/01-auto/auto101.cfm | G16: 46295 | H16: California | I16: Regulator-published | J16: Primary source | K16: 46295
A17: Fault and claims | B17: Reasons a policy can be cancelled or non-renewed | C17: Fraud/material misrepresentation; non-payment; substantial increase in hazard | D17: CDI Form 101 | E17: CA Dept of Insurance - Introduction to Auto Insurance (Form 101, rev. Feb 5, 2025) | F17: https://www.insurance.ca.gov/01-consumers/105-type/95-guides/01-auto/auto101.cfm | G17: 46295 | H17: California | I17: Regulator-published | J17: Primary source | K17: 46295
A18: Rating factors | B18: Mandatory factors (in order of importance) | C18: 1) driving safety record 2) annual miles 3) years of driving experience | D18: Ins. Code 1861.02(a); 10 CCR 2632.5(c) | E18: 10 CCR section 2632.5 - Rating Factors (text via Cornell LII) | F18: https://www.law.cornell.edu/regulations/california/10-CCR-2632.5 | G18: 46295 | H18: California | I18: Statute / regulation text | J18: Primary source | K18: 46295 | L18: Factors after the third must be on the Commissioner's approved list.
A19: Rating factors | B19: Optional factors currently listed | C19: Vehicle type; performance; type of use; percent use; multi-vehicle household; academic standing; driver training; vehicle characteristics; marital status; persistency; non-smoker; secondary driver characteristics; multi-policy; relative claims frequency; relative claims severity | D19: 10 CCR 2632.5(d) | E19: 10 CCR section 2632.5 - Rating Factors (text via Cornell LII) | F19: https://www.law.cornell.edu/regulations/california/10-CCR-2632.5 | G19: 46295 | H19: California | I19: Statute / regulation text | J19: Primary source | K19: 46295 | L19: Advisory Notice 2005-02 counted 16 optional factors; one was repealed effective Jan 1, 2019 (reported as gender). Confirm.
A20: Rating factors | B20: Location | C20: Only through claims frequency and severity bands, each max 20 categories, based on ZIP code or census tract where vehicle is garaged | D20: 10 CCR 2632.5(d)(14)-(15) | E20: 10 CCR section 2632.5 - Rating Factors (text via Cornell LII) | F20: https://www.law.cornell.edu/regulations/california/10-CCR-2632.5 | G20: 46295 | H20: California | I20: Statute / regulation text | J20: Primary source | K20: 46295
A21: Rating factors | B21: Credit history, gender, age | C21: Not on the mandatory or optional lists | D21: 10 CCR 2632.5 | E21: 10 CCR section 2632.5 - Rating Factors (text via Cornell LII) | F21: https://www.law.cornell.edu/regulations/california/10-CCR-2632.5 | G21: 46295 | H21: California | I21: Statute / regulation text | J21: Primary source | K21: 46295 | L21: Derived from the regulation text: age matters only via years licensed. Confirm with counsel before publishing as a legal statement.
A22: Rating factors | B22: Driving record verification | C22: Insurer must verify the motor vehicle report at application and at least every 36 months; DUI convictions treated as highest surchargeable violation | D22: 10 CCR 2632.5(c)(1) | E22: 10 CCR section 2632.5 - Rating Factors (text via Cornell LII) | F22: https://www.law.cornell.edu/regulations/california/10-CCR-2632.5 | G22: 46295 | H22: California | I22: Statute / regulation text | J22: Primary source | K22: 46295
A23: Mileage and telematics | B23: How mileage is set | C23: Estimated annual miles, with insurer allowed to request supporting information; verified-actual-mileage programs also allowed | D23: 10 CCR 2632.5(c)(2) | E23: 10 CCR section 2632.5 - Rating Factors (text via Cornell LII) | F23: https://www.law.cornell.edu/regulations/california/10-CCR-2632.5 | G23: 46295 | H23: California | I23: Statute / regulation text | J23: Primary source | K23: 46295
A24: Mileage and telematics | B24: Device restrictions | C24: Insurer may use a device only to collect actual miles driven and may not collect or store vehicle location (exceptions for roadside, theft, map, travel services) | D24: 10 CCR 2632.5(c)(2)(F)(i)5 | E24: 10 CCR section 2632.5 - Rating Factors (text via Cornell LII) | F24: https://www.law.cornell.edu/regulations/california/10-CCR-2632.5 | G24: 46295 | H24: California | I24: Statute / regulation text | J24: Primary source | K24: 46295 | L24: This may explain why behavior-based programs like Snapshot and Drivewise are not offered in CA. That link is my inference.
A25: Discounts | B25: Good driver discount | C25: Rate at least 20% lower than a comparable non-good driver | D25: Ins. Code 1861.02; 10 CCR 2632.12; CDI Form 101 | E25: 10 CCR section 2632.12 - Good Driver Discount (text via Cornell LII) | F25: https://www.law.cornell.edu/regulations/california/10-CCR-2632.12 | G25: 46295 | H25: California | I25: Statute / regulation text | J25: Primary source | K25: 46295 | L25: See statute row below for eligibility.
A26: Discounts | B26: Good driver eligibility (statute) | C26: Licensed for the previous three years, and in that period: no more than one violation point (an at-fault property-damage accident counts as one point), no more than one non-confidential dismissal that would have carried more than one point, and not principally at fault in an accident causing injury or death | D26: Ins. Code 1861.025(a)-(b) | E26: CA Insurance Code section 1861.025 - Good Driver Discount eligibility (Justia) | F26: https://law.justia.com/codes/california/code-ins/division-1/part-2/chapter-9/article-10/section-1861-025/ | G26: 46295 | H26: California | I26: Statute / regulation text | J26: Primary source | K26: 46295 | L26: CDI's consumer page mentions only the point limit. Further criteria in later subdivisions were not visible in the text I read; have counsel confirm before publishing eligibility rules.
A27: Discounts | B27: Six-month vs annual policy | C27: Six-month premium must be one-half of the annual premium; no paid-in-full discount | D27: CDI Advisory Notice 2005-02 | E27: CDI Rate Regulation Advisory Notice 2005-02 (May 2, 2005) | F27: https://www.insurance.ca.gov/0250-insurers/0300-insurers/0200-bulletins/bulletin-notices-commiss-opinion/upload/Advisory-Notice-2005-02.pdf | G27: 46295 | H27: California | I27: Regulator-published | J27: Primary source | K27: 46295 | L27: Dated May 2, 2005; confirm not superseded. Matters for your policy-term comparison feature.
A28: Discounts | B28: Mature driver (55+) with DMV-approved course | C28: Every admitted insurer must provide a reduction; insurer sets the percentage | D28: Ins. Code 11628.3; 13 CCR 346.00 | E28: CA Insurance Code section 11628.3 - Mature driver (text via FindLaw) | F28: https://codes.findlaw.com/ca/insurance-code/ins-sect-11628-3/ | G28: 46295 | H28: California | I28: Statute / regulation text | J28: Primary source | K28: 46295 | L28: FindLaw may lag the latest law.
A29: Programs | B29: Low Cost Auto (CLCA) | C29: Limits 10/20/3; income at or below 250% of federal poverty level; vehicle worth $25,000 or less; age 16+ | D29: CDI Form 101 | E29: CA Dept of Insurance - Introduction to Auto Insurance (Form 101, rev. Feb 5, 2025) | F29: https://www.insurance.ca.gov/01-consumers/105-type/95-guides/01-auto/auto101.cfm | G29: 46295 | H29: California | I29: Regulator-published | J29: Primary source | K29: 46295 | L29: CLCA limits unchanged by SB 1107 (CDI alert).
A30: Programs | B30: High-risk drivers (CAARP) | C30: Assigned to an insurer; all licensed insurers must accept; same premiums across companies | D30: CDI Form 101 | E30: CA Dept of Insurance - Introduction to Auto Insurance (Form 101, rev. Feb 5, 2025) | F30: https://www.insurance.ca.gov/01-consumers/105-type/95-guides/01-auto/auto101.cfm | G30: 46295 | H30: California | I30: Regulator-published | J30: Primary source | K30: 46295
A31: Agents and brokers | B31: Licensing and pay | C31: All agents and brokers must be state licensed; agents paid by insurers; brokers may charge a broker fee | D31: CDI Form 101 | E31: CA Dept of Insurance - Introduction to Auto Insurance (Form 101, rev. Feb 5, 2025) | F31: https://www.insurance.ca.gov/01-consumers/105-type/95-guides/01-auto/auto101.cfm | G31: 46295 | H31: California | I31: Regulator-published | J31: Primary source | K31: 46295 | L31: Relevant to your referral and lead-generation model.
A32: Quotes | B32: What CDI calls a quote | C32: An estimate of premium; get quotes in writing and compare | D32: CDI Form 101 | E32: CA Dept of Insurance - Introduction to Auto Insurance (Form 101, rev. Feb 5, 2025) | F32: https://www.insurance.ca.gov/01-consumers/105-type/95-guides/01-auto/auto101.cfm | G32: 46295 | H32: California | I32: Regulator-published | J32: Primary source | K32: 46295 | L32: Supports your 'estimate vs actual quote' labels.

Sheet CA Home Verified
A1: Topic | B1: Fact | C1: Value | D1: Legal Citation | E1: Source | F1: Source URL | G1: Date Collected | H1: Geographic Scope | I1: Data Type | J1: Verification Status | K1: Last Updated | L1: Notes
A2: Requirement | B2: Is homeowners insurance required? | C2: No. Lenders require enough coverage; lenders require flood insurance in federally mapped high-risk flood zones | D2: CDI Homeowners flyer (Dec 2024) | E2: CA Dept of Insurance - Homeowners Insurance flyer (Dec 2024) | F2: https://www.insurance.ca.gov/01-consumers/105-type/95-guides/upload/Homeowners-Insurance-Updated-121924.pdf | G2: 46295 | H2: California | I2: Regulator-published | J2: Primary source | K2: 46295
A3: Coverage | B3: Coverage A - Dwelling | C3: Protects the house and attached structures from covered perils | D3: CDI Form 401 | E3: CA Dept of Insurance - Residential Insurance: Homeowners and Renters (Form 401, rev. Jan 2026) | F3: https://www.insurance.ca.gov/01-consumers/105-type/95-guides/03-res/res-ins-guide.cfm | G3: 46295 | H3: California | I3: Regulator-published | J3: Primary source | K3: 46295
A4: Coverage | B4: Coverage B - Other structures | C4: Normally limited to 10% of Coverage A; more available for extra premium | D4: CDI Form 401 | E4: CA Dept of Insurance - Residential Insurance: Homeowners and Renters (Form 401, rev. Jan 2026) | F4: https://www.insurance.ca.gov/01-consumers/105-type/95-guides/03-res/res-ins-guide.cfm | G4: 46295 | H4: California | I4: Regulator-published | J4: Primary source | K4: 46295
A5: Coverage | B5: Coverage C - Personal property | C5: Contents limit generally about 50% of dwelling (a guideline only); special limits on jewelry, antiques, furs, collectibles, fine art, firearms, silverware, money | D5: CDI Form 401 | E5: CA Dept of Insurance - Residential Insurance: Homeowners and Renters (Form 401, rev. Jan 2026) | F5: https://www.insurance.ca.gov/01-consumers/105-type/95-guides/03-res/res-ins-guide.cfm | G5: 46295 | H5: California | I5: Regulator-published | J5: Primary source | K5: 46295 | L5: Special limits sit inside the overall contents limit, not on top of it; scheduling items separately is the fix.
A6: Coverage | B6: Coverage D - Loss of use | C6: Normally limited to 20% of Coverage A (renters: 20% of C; condo: 40% of C) | D6: CDI Form 401 | E6: CA Dept of Insurance - Residential Insurance: Homeowners and Renters (Form 401, rev. Jan 2026) | F6: https://www.insurance.ca.gov/01-consumers/105-type/95-guides/03-res/res-ins-guide.cfm | G6: 46295 | H6: California | I6: Regulator-published | J6: Primary source | K6: 46295
A7: Coverage | B7: Coverage E and F | C7: E: personal liability. F: medical payments to others (not for household members) | D7: CDI Form 401 | E7: CA Dept of Insurance - Residential Insurance: Homeowners and Renters (Form 401, rev. Jan 2026) | F7: https://www.insurance.ca.gov/01-consumers/105-type/95-guides/03-res/res-ins-guide.cfm | G7: 46295 | H7: California | I7: Regulator-published | J7: Primary source | K7: 46295
A8: Coverage | B8: Perils generally NOT covered | C8: Flood, earthquake, earth movement, termites and pests, seepage/leaks, vacancy of 60+ days, mold, wear and tear, war, neglect, nuclear hazard | D8: CDI Form 401 | E8: CA Dept of Insurance - Residential Insurance: Homeowners and Renters (Form 401, rev. Jan 2026) | F8: https://www.insurance.ca.gov/01-consumers/105-type/95-guides/03-res/res-ins-guide.cfm | G8: 46295 | H8: California | I8: Regulator-published | J8: Primary source | K8: 46295 | L8: Read the actual policy exclusions.
A9: Limits | B9: How to set the dwelling limit | C9: Should equal the cost to rebuild, not purchase price or market value; land is not covered | D9: CDI Form 401 | E9: CA Dept of Insurance - Residential Insurance: Homeowners and Renters (Form 401, rev. Jan 2026) | F9: https://www.insurance.ca.gov/01-consumers/105-type/95-guides/03-res/res-ins-guide.cfm | G9: 46295 | H9: California | I9: Regulator-published | J9: Primary source | K9: 46295
A10: Limits | B10: Replacement cost estimates | C10: If an insurer or broker gives a replacement cost estimate, a copy must be given to the applicant or insured who buys the coverage | D10: CDI Form 401 | E10: CA Dept of Insurance - Residential Insurance: Homeowners and Renters (Form 401, rev. Jan 2026) | F10: https://www.insurance.ca.gov/01-consumers/105-type/95-guides/03-res/res-ins-guide.cfm | G10: 46295 | H10: California | I10: Regulator-published | J10: Primary source | K10: 46295 | L10: Relevant if your site ever shows a rebuild-cost estimate.
A11: Limits | B11: 'Guaranteed replacement cost' label | C11: May be used only if the policy pays to fully rebuild regardless of the limit; other forms pay the limit plus a percentage; SB 1855 renamed 'Extended' to 'Limited Replacement Cost' in disclosures | D11: CDI Form 401 | E11: CA Dept of Insurance - Residential Insurance: Homeowners and Renters (Form 401, rev. Jan 2026) | F11: https://www.insurance.ca.gov/01-consumers/105-type/95-guides/03-res/res-ins-guide.cfm | G11: 46295 | H11: California | I11: Regulator-published | J11: Primary source | K11: 46295
A12: Limits | B12: Building code upgrade (ordinance or law) | C12: Some policies lack it; available by endorsement | D12: CDI Form 401 | E12: CA Dept of Insurance - Residential Insurance: Homeowners and Renters (Form 401, rev. Jan 2026) | F12: https://www.insurance.ca.gov/01-consumers/105-type/95-guides/03-res/res-ins-guide.cfm | G12: 46295 | H12: California | I12: Regulator-published | J12: Primary source | K12: 46295
A13: Limits | B13: Actual cash value (ACV) | C13: Total loss: lesser of policy limit or fair market value. Partial loss: repair cost minus depreciation, or the limit | D13: CDI Form 401 glossary | E13: CA Dept of Insurance - Residential Insurance: Homeowners and Renters (Form 401, rev. Jan 2026) | F13: https://www.insurance.ca.gov/01-consumers/105-type/95-guides/03-res/res-ins-guide.cfm | G13: 46295 | H13: California | I13: Regulator-published | J13: Primary source | K13: 46295
A14: Discounts | B14: Discounts named by CDI | C14: Burglar alarms and fire protection devices such as smoke detectors, alarms and sprinklers; higher deductible can significantly cut premium | D14: CDI Form 401 | E14: CA Dept of Insurance - Residential Insurance: Homeowners and Renters (Form 401, rev. Jan 2026) | F14: https://www.insurance.ca.gov/01-consumers/105-type/95-guides/03-res/res-ins-guide.cfm | G14: 46295 | H14: California | I14: Regulator-published | J14: Primary source | K14: 46295
A15: Discounts | B15: Safer from Wildfires | C15: Every action under the framework qualifies for an insurance discount (structure, surroundings, community) | D15: 10 CCR 2644.9 (CDI page) | E15: CA Dept of Insurance - Safer from Wildfires | F15: https://www.insurance.ca.gov/01-consumers/200-wrr/Safer-from-Wildfires.cfm | G15: 46295 | H15: California | I15: Regulator-published | J15: Primary source | K15: 46295 | L15: Secondary sites often cite this as 'Insurance Code 2644.9'; it is a Title 10 regulation.
A16: Discounts | B16: Disclosure and appeal of wildfire risk score | C16: Insurers must disclose available discounts and the policyholder's risk score, and allow an appeal | D16: 10 CCR 2644.9 (per research paper) | E16: Resources for the Future - Insurance discounts for wildfire mitigation (WP 25-30) | F16: https://media.rff.org/documents/WP_25-30.pdf | G16: 46295 | H16: California | I16: Reference data (secondary source) | J16: Secondary - unverified | K16: 46295 | L16: Confirm in the regulation text.
A17: Rates | B17: Who approves rates | C17: Each insurer calculates its own rates, subject to CDI approval | D17: CDI residential one-pager | E17: CA Dept of Insurance - Residential Insurance: Homeowners and Renters (Form 401, rev. Jan 2026) | F17: https://www.insurance.ca.gov/01-consumers/105-type/95-guides/03-res/res-ins-guide.cfm | G17: 46295 | H17: California | I17: Regulator-published | J17: Primary source | K17: 46295 | L17: Snippet of the one-pager was truncated; confirm wording.
A18: Rights | B18: Cancellation | C18: After 60 days, only for nonpayment, fraud, material misrepresentation, or physical changes that increase hazard; 20 days' notice (10 for nonpayment or fraud) | D18: CDI Form 401 | E18: CA Dept of Insurance - Residential Insurance: Homeowners and Renters (Form 401, rev. Jan 2026) | F18: https://www.insurance.ca.gov/01-consumers/105-type/95-guides/03-res/res-ins-guide.cfm | G18: 46295 | H18: California | I18: Regulator-published | J18: Primary source | K18: 46295
A19: Rights | B19: Nonrenewal | C19: Written notice at least 75 days before expiration with the reason; if late, the existing policy stays in effect 75 days from notice | D19: CDI Form 401 | E19: CA Dept of Insurance - Residential Insurance: Homeowners and Renters (Form 401, rev. Jan 2026) | F19: https://www.insurance.ca.gov/01-consumers/105-type/95-guides/03-res/res-ins-guide.cfm | G19: 46295 | H19: California | I19: Regulator-published | J19: Primary source | K19: 46295
A20: Rights | B20: Premium verification | C20: Insurer has 60 days to verify rating and underwriting of a new policy and notify of errors | D20: CDI Form 401 | E20: CA Dept of Insurance - Residential Insurance: Homeowners and Renters (Form 401, rev. Jan 2026) | F20: https://www.insurance.ca.gov/01-consumers/105-type/95-guides/03-res/res-ins-guide.cfm | G20: 46295 | H20: California | I20: Regulator-published | J20: Primary source | K20: 46295
A21: Rights | B21: Time to rebuild (AB 2199) | C21: At least 12 months (plus 6-month extensions for good cause); 24 months after a declared emergency; may rebuild elsewhere | D21: CDI Form 401 | E21: CA Dept of Insurance - Residential Insurance: Homeowners and Renters (Form 401, rev. Jan 2026) | F21: https://www.insurance.ca.gov/01-consumers/105-type/95-guides/03-res/res-ins-guide.cfm | G21: 46295 | H21: California | I21: Regulator-published | J21: Primary source | K21: 46295
A22: Rights | B22: Total loss protections (AB 2962) | C22: Insurer must consult at renewal; cannot cancel mid-rebuild except for fraud; must renew at least once after a declared-disaster total loss not caused by negligence | D22: CDI Form 401 | E22: CA Dept of Insurance - Residential Insurance: Homeowners and Renters (Form 401, rev. Jan 2026) | F22: https://www.insurance.ca.gov/01-consumers/105-type/95-guides/03-res/res-ins-guide.cfm | G22: 46295 | H22: California | I22: Regulator-published | J22: Primary source | K22: 46295
A23: Rights | B23: Wildfire non-renewal moratorium | C23: Bars non-renewal of residential policies for one year after a declared wildfire (SB 824); SB 547 extends this to commercial policies from Jan 1, 2026 | D23: CDI press release Dec 30, 2025 | E23: CDI press release - New laws take effect January 1, 2026 (Dec 30, 2025) | F23: https://www.insurance.ca.gov/0400-news/0100-press-releases/2025/release079-2025.cfm | G23: 46295 | H23: California | I23: Regulator-published | J23: Primary source | K23: 46295 | L23: Zones covered are set by CDI; check the current list.
A24: Rights | B24: Contents payout without inventory (SB 495) | C24: Wildfire total loss: 60% of contents limit, capped at $350,000, without a detailed list; at least 100 days for proof of loss after a declared emergency | D24: CDI press release Dec 30, 2025 (effective Jan 1, 2026) | E24: CDI press release - New laws take effect January 1, 2026 (Dec 30, 2025) | F24: https://www.insurance.ca.gov/0400-news/0100-press-releases/2025/release079-2025.cfm | G24: 46295 | H24: California | I24: Regulator-published | J24: Primary source | K24: 46295
A25: New laws (2026) | B25: AB 1, AB 226, AB 888, SB 429 | C25: AB 1: regular review of Safer from Wildfires. AB 226: FAIR Plan may use catastrophe bonds and credit lines if authorized. AB 888: grants for fire-safe roofs and Zone Zero. SB 429: grants for a public wildfire model | D25: CDI press release Dec 30, 2025 (effective Jan 1, 2026) | E25: CDI press release - New laws take effect January 1, 2026 (Dec 30, 2025) | F25: https://www.insurance.ca.gov/0400-news/0100-press-releases/2025/release079-2025.cfm | G25: 46295 | H25: California | I25: Regulator-published | J25: Primary source | K25: 46295
A26: Earthquake | B26: Must insurers offer it? | C26: Yes. No residential property policy may be issued or renewed unless the insured is offered earthquake coverage; it may be written by the insurer, another insurer, or the CEA | D26: Ins. Code 10081; CDI Form 401 | E26: CA Dept of Insurance - Earthquake Insurance | F26: https://www.insurance.ca.gov/01-consumers/105-type/95-guides/03-res/eq-ins.cfm | G26: 46295 | H26: California | I26: Regulator-published | J26: Primary source | K26: 46295
A27: Earthquake | B27: Re-offer schedule | C27: If declined, the insurer must re-offer earthquake coverage every other year at continuation, renewal or reinstatement; the offer may be made before, at, or within 60 days after issuance or renewal | D27: Ins. Code 10083(a)-(b) | E27: CA Insurance Code section 10083 - Earthquake offer timing (Justia) | F27: https://law.justia.com/codes/california/code-ins/division-2/part-1/chapter-8-5/section-10083/ | G27: 46295 | H27: California | I27: Statute / regulation text | J27: Primary source | K27: 46295 | L27: Confirms the every-other-year rule that earlier came only from agency sites.
A28: Earthquake | B28: Fire after earthquake | C28: Homeowners and renters policies must cover fire damage caused by or following an earthquake | D28: CDI earthquake page | E28: CA Dept of Insurance - Earthquake Insurance | F28: https://www.insurance.ca.gov/01-consumers/105-type/95-guides/03-res/eq-ins.cfm | G28: 46295 | H28: California | I28: Regulator-published | J28: Primary source | K28: 46295
A29: Earthquake | B29: What earthquake insurance does not cover | C29: Vehicles; flood, sewer/drain backup, tsunami | D29: CDI earthquake page | E29: CA Dept of Insurance - Earthquake Insurance | F29: https://www.insurance.ca.gov/01-consumers/105-type/95-guides/03-res/eq-ins.cfm | G29: 46295 | H29: California | I29: Regulator-published | J29: Primary source | K29: 46295
A30: Earthquake | B30: Claim reporting | C30: Insurer can deny claims not reported within one year | D30: CDI earthquake brochure | E30: CA Dept of Insurance - Earthquake Insurance | F30: https://www.insurance.ca.gov/01-consumers/105-type/95-guides/03-res/eq-ins.cfm | G30: 46295 | H30: California | I30: Regulator-published | J30: Primary source | K30: 46295 | L30: From a truncated brochure snippet; confirm.
A31: Earthquake | B31: CEA deductible options | C31: 5%, 10%, 15%, 20%, 25% of dwelling coverage; homes over $1M dwelling limit or pre-1980 raised-foundation homes without verified retrofit only get 15%-25% | D31: CEA homeowners page | E31: California Earthquake Authority - Homeowners policies | F31: https://www.earthquakeauthority.com/california-earthquake-insurance-policies/homeowners | G31: 46295 | H31: California | I31: Regulator-published | J31: Primary source | K31: 46295 | L31: Premium and take-up figures remain secondary; see Coverage Details.
A32: Earthquake | B32: CEA retrofit discount and loss of use | C32: Discount up to 25% for retrofit; loss of use never has a deductible | D32: CEA homeowners page | E32: California Earthquake Authority - Homeowners policies | F32: https://www.earthquakeauthority.com/california-earthquake-insurance-policies/homeowners | G32: 46295 | H32: California | I32: Regulator-published | J32: Primary source | K32: 46295
A33: Flood | B33: Is flood covered? | C33: Generally excluded from homeowners and renters policies; NFIP (FEMA) offers it; CDI does not regulate the NFIP | D33: CDI Form 401; CDI flood page | E33: CA Dept of Insurance - Flood Insurance Resources | F33: https://www.insurance.ca.gov/01-consumers/140-catastrophes/FloodFacts.cfm | G33: 46295 | H33: California | I33: Regulator-published | J33: Primary source | K33: 46295
A34: Flood | B34: NFIP maximums, single-family | C34: $250,000 structure; $100,000 contents; renters up to $100,000 contents | D34: CDI Form 401 | E34: CA Dept of Insurance - Residential Insurance: Homeowners and Renters (Form 401, rev. Jan 2026) | F34: https://www.insurance.ca.gov/01-consumers/105-type/95-guides/03-res/res-ins-guide.cfm | G34: 46295 | H34: California | I34: Regulator-published | J34: Primary source | K34: 46295 | L34: Federal program authorization status must be checked live; see Coverage Details.
A35: Flood | B35: FAIR Plan and storms | C35: FAIR Plan does not cover storm-related damage unless the owner buys a supplemental 'difference in conditions' (DIC) policy from another insurer | D35: CDI flood page | E35: CA Dept of Insurance - Flood Insurance Resources | F35: https://www.insurance.ca.gov/01-consumers/140-catastrophes/FloodFacts.cfm | G35: 46295 | H35: California | I35: Regulator-published | J35: Primary source | K35: 46295
A36: FAIR Plan | B36: What it is | C36: Association of all licensed property insurers; insurer of last resort | D36: CDI Form 401; FAIR Plan site | E36: CA Dept of Insurance - Residential Insurance: Homeowners and Renters (Form 401, rev. Jan 2026) | F36: https://www.insurance.ca.gov/01-consumers/105-type/95-guides/03-res/res-ins-guide.cfm | G36: 46295 | H36: California | I36: Regulator-published | J36: Primary source | K36: 46295
A37: FAIR Plan | B37: What it covers | C37: Standard fire policy for structure and contents; basic property policy with limits; no liability or other perils such as burglary | D37: CDI Form 401 | E37: CA Dept of Insurance - Residential Insurance: Homeowners and Renters (Form 401, rev. Jan 2026) | F37: https://www.insurance.ca.gov/01-consumers/105-type/95-guides/03-res/res-ins-guide.cfm | G37: 46295 | H37: California | I37: Regulator-published | J37: Primary source | K37: 46295 | L37: CDI suggests a DIC or supplemental policy from a private insurer.
A38: FAIR Plan | B38: Broker fees | C38: Broker may not charge a fee for a FAIR Plan submission | D38: CDI Form 401 | E38: CA Dept of Insurance - Residential Insurance: Homeowners and Renters (Form 401, rev. Jan 2026) | F38: https://www.insurance.ca.gov/01-consumers/105-type/95-guides/03-res/res-ins-guide.cfm | G38: 46295 | H38: California | I38: Regulator-published | J38: Primary source | K38: 46295
A39: FAIR Plan | B39: Dwelling limit | C39: $3 million per property | D39: CDI press release 2019 (effective Apr 1, 2020); Assembly Insurance Committee | E39: CDI press release 089-19 - FAIR Plan coverage options | F39: https://www.insurance.ca.gov/0400-news/0100-press-releases/2019/release089-19.cfm | G39: 46295 | H39: California | I39: Regulator-published | J39: Primary source | K39: 46295 | L39: Confirm current limit on the FAIR Plan site.
A40: FAIR Plan | B40: 2026 rate change | C40: CDI approved a 29.1% average dwelling increase (FAIR Plan asked for 35.8%), effective Oct 15, 2026 per news reports | D40: News reports, not the CDI decision | E40: KQED - FAIR Plan announces 29.1% rate hike (Aug 2026) | F40: https://www.kqed.org/news/12094860/california-fair-plan-announces-29-1-rate-hike-for-homeowners-this-fall | G40: 46295 | H40: California | I40: Reference data (secondary source) | J40: Secondary - unverified | K40: 46295 | L40: Replaces the earlier 'sought 35.8%' note. Verify in the CDI order.
...

Sheet TX Auto Verified
A1: Topic | B1: Fact | C1: Value | D1: Legal Citation | E1: Source | F1: Source URL | G1: Date Collected | H1: Geographic Scope | I1: Data Type | J1: Verification Status | K1: Last Updated | L1: Notes
A2: Minimum liability | B2: Bodily injury and property damage | C2: 30/60/25: $30,000 per person, $60,000 per accident, $25,000 property damage | D2: TDI guide (Transportation Code 601.072 per secondary sources) | E2: Texas Dept of Insurance - Auto insurance guide (CB020) | F2: https://www.tdi.texas.gov/pubs/consumer/cb020.html | G2: 46295 | H2: Texas | I2: Regulator-published | J2: Primary source | K2: 46295 | L2: TDI: collision and comprehensive are required only by lenders.
A3: Other coverages | B3: Personal injury protection (PIP) | C3: Included on auto policies; the insured must reject it in writing | D3: TDI guide | E3: Texas Dept of Insurance - Auto insurance guide (CB020) | F3: https://www.tdi.texas.gov/pubs/consumer/cb020.html | G3: 46295 | H3: Texas | I3: Regulator-published | J3: Primary source | K3: 46295 | L3: PIP dollar amount not stated by TDI.
A4: Other coverages | B4: PIP amount | C4: Insurers must offer $2,500 | D4: Law-firm blog | E4: Ashmore Law Firm - Car insurance: do you have enough? | F4: https://www.ashmorelaw.com/blog/car-insurance-do-you-have-enough-.cfm | G4: 46295 | H4: Texas | I4: Reference data (secondary source) | J4: Secondary - unverified | K4: 46295 | L4: Confirm in Insurance Code chapter 1952.
A5: Other coverages | B5: Uninsured/underinsured motorist | C5: Insurers must offer it; rejection must be in writing | D5: TDI guide | E5: Texas Dept of Insurance - Auto insurance guide (CB020) | F5: https://www.tdi.texas.gov/pubs/consumer/cb020.html | G5: 46295 | H5: Texas | I5: Regulator-published | J5: Primary source | K5: 46295
A6: Other coverages | B6: Medical payments | C6: Optional; pays medical bills for you and passengers | D6: TDI guide | E6: Texas Dept of Insurance - Auto insurance guide (CB020) | F6: https://www.tdi.texas.gov/pubs/consumer/cb020.html | G6: 46295 | H6: Texas | I6: Regulator-published | J6: Primary source | K6: 46295
A7: Rates | B7: Rate approval | C7: No prior approval; TDI can order refunds if rates are too high; rates must be fair, reasonable and adequate | D7: TDI guide | E7: Texas Dept of Insurance - Auto insurance guide (CB020) | F7: https://www.tdi.texas.gov/pubs/consumer/cb020.html | G7: 46295 | H7: Texas | I7: Regulator-published | J7: Primary source | K7: 46295
A8: Rating | B8: Prohibited factors | C8: Race, color, religion, national origin may not be used to deny or charge more | D8: TDI guide | E8: Texas Dept of Insurance - Auto insurance guide (CB020) | F8: https://www.tdi.texas.gov/pubs/consumer/cb020.html | G8: 46295 | H8: Texas | I8: Regulator-published | J8: Primary source | K8: 46295
A9: Rating | B9: Age, gender, marital status, location, disability | C9: Allowed only if the company can show a greater risk of loss | D9: TDI guide | E9: Texas Dept of Insurance - Auto insurance guide (CB020) | F9: https://www.tdi.texas.gov/pubs/consumer/cb020.html | G9: 46295 | H9: Texas | I9: Regulator-published | J9: Primary source | K9: 46295
A10: Rating | B10: Credit score | C10: May be used, but not as the only reason to turn you down or charge more; HelpInsure.com shows which companies use it | D10: TDI guide | E10: Texas Dept of Insurance - Auto insurance guide (CB020) | F10: https://www.tdi.texas.gov/pubs/consumer/cb020.html | G10: 46295 | H10: Texas | I10: Regulator-published | J10: Primary source | K10: 46295
A11: Rating | B11: Other factors TDI names | C11: Driving record and claims history (CLUE), where the car is kept, vehicle type, how the car is used, credit score | D11: TDI guide | E11: Texas Dept of Insurance - Auto insurance guide (CB020) | F11: https://www.tdi.texas.gov/pubs/consumer/cb020.html | G11: 46295 | H11: Texas | I11: Regulator-published | J11: Primary source | K11: 46295
A12: Discounts | B12: Discounts | C12: Each company decides what to offer and the amount | D12: TDI guide | E12: Texas Dept of Insurance - Auto insurance guide (CB020) | F12: https://www.tdi.texas.gov/pubs/consumer/cb020.html | G12: 46295 | H12: Texas | I12: Regulator-published | J12: Primary source | K12: 46295 | L12: Examples TDI lists: airbags/ABS/antitheft, defensive driving or driver education, multi-car, multi-policy, no claims.
A13: Policy changes | B13: Cancellation | C13: 10 days' notice; any reason in first 60 days; afterwards only nonpayment, fraudulent claim, or suspended license/registration; unearned premium refunded within 15 days | D13: TDI guide | E13: Texas Dept of Insurance - Auto insurance guide (CB020) | F13: https://www.tdi.texas.gov/pubs/consumer/cb020.html | G13: 46295 | H13: Texas | I13: Regulator-published | J13: Primary source | K13: 46295
A14: Policy changes | B14: Nonrenewal | C14: Written reason; 60 days' notice if bought or renewed in 2024 (30 days for 2023 or earlier); only after 12 months in effect; no nonrenewal for age or certain claims (weather, hitting an animal, not-at-fault, flying objects) | D14: TDI guide | E14: Texas Dept of Insurance - Auto insurance guide (CB020) | F14: https://www.tdi.texas.gov/pubs/consumer/cb020.html | G14: 46295 | H14: Texas | I14: Regulator-published | J14: Conflicting | K14: 46295 | L14: Wording is date-specific; confirm the current notice period with TDI.
A15: Programs | B15: Texas Automobile Insurance Plan (TAIPA) | C15: Available after two insurers decline; liability, PIP and UM/UIM only; no collision, comprehensive or higher limits; cheaper policy must be offered after 3 clean years | D15: TDI guide | E15: Texas Dept of Insurance - Auto insurance guide (CB020) | F15: https://www.tdi.texas.gov/pubs/consumer/cb020.html | G15: 46295 | H15: Texas | I15: Regulator-published | J15: Primary source | K15: 46295
A16: Claims | B16: Deadlines | C16: Acknowledge within 15 days; accept or reject within 15 business days of receiving information (45 days if more time needed); pay within 5 business days of agreeing | D16: TDI guide | E16: Texas Dept of Insurance - Auto insurance guide (CB020) | F16: https://www.tdi.texas.gov/pubs/consumer/cb020.html | G16: 46295 | H16: Texas | I16: Regulator-published | J16: Primary source | K16: 46295 | L16: Prompt-pay rules do not apply when another driver's insurer pays.
A17: Claims | B17: Settlement basis | C17: Actual cash value; parts of like kind and quality; insurer cannot require preferred shops | D17: TDI guide | E17: Texas Dept of Insurance - Auto insurance guide (CB020) | F17: https://www.tdi.texas.gov/pubs/consumer/cb020.html | G17: 46295 | H17: Texas | I17: Regulator-published | J17: Primary source | K17: 46295
A18: Claims | B18: Disputes | C18: Appraisal, TDI complaint (in writing), or court (Justice Court for claims under $10,000) | D18: TDI guide | E18: Texas Dept of Insurance - Auto insurance guide (CB020) | F18: https://www.tdi.texas.gov/pubs/consumer/cb020.html | G18: 46295 | H18: Texas | I18: Regulator-published | J18: Primary source | K18: 46295
A19: Consumer rights | B19: Auto Consumer Bill of Rights | C19: Insurer must give a copy when you get or renew a policy | D19: TDI guide | E19: Texas Dept of Insurance - Auto insurance guide (CB020) | F19: https://www.tdi.texas.gov/pubs/consumer/cb020.html | G19: 46295 | H19: Texas | I19: Regulator-published | J19: Primary source | K19: 46295

Sheet FL Auto Verified
A1: Topic | B1: Fact | C1: Value | D1: Legal Citation | E1: Source | F1: Source URL | G1: Date Collected | H1: Geographic Scope | I1: Data Type | J1: Verification Status | K1: Last Updated | L1: Notes
A2: Requirement | B2: Coverage required to register | C2: PIP $10,000 and property damage liability $10,000 for vehicles with at least four wheels | D2: FLHSMV; s. 627.736 and 324.022 per secondary sources | E2: Florida DHSMV - Florida Insurance Requirements | F2: https://www.flhsmv.gov/insurance/ | G2: 46295 | H2: Florida | I2: Regulator-published | J2: Primary source | K2: 46295
A3: Requirement | B3: PIP benefit | C3: Pays 80% of necessary and reasonable medical expenses up to $10,000, regardless of fault | D3: FLHSMV | E3: Florida DHSMV - Florida Insurance Requirements | F3: https://www.flhsmv.gov/insurance/ | G3: 46295 | H3: Florida | I3: Regulator-published | J3: Primary source | K3: 46295
A4: Requirement | B4: Bodily injury liability | C4: Not required for most private passenger vehicles; taxis must carry $125,000/$250,000/$50,000 | D4: FLHSMV | E4: Florida DHSMV - Florida Insurance Requirements | F4: https://www.flhsmv.gov/insurance/ | G4: 46295 | H4: Florida | I4: Regulator-published | J4: Primary source | K4: 46295
A5: Requirement | B5: Continuous coverage | C5: Required even if the vehicle is not driven; surrender the plate before cancelling insurance | D5: FLHSMV | E5: Florida DHSMV - Florida Insurance Requirements | F5: https://www.flhsmv.gov/insurance/ | G5: 46295 | H5: Florida | I5: Regulator-published | J5: Primary source | K5: 46295
A6: Penalties | B6: Lapse consequences | C6: Driving privilege and plate can be suspended up to 3 years; reinstatement fee up to $500; no hardship license | D6: FLHSMV | E6: Florida DHSMV - Florida Insurance Requirements | F6: https://www.flhsmv.gov/insurance/ | G6: 46295 | H6: Florida | I6: Regulator-published | J6: Primary source | K6: 46295
A7: Financial responsibility | B7: After a crash | C7: Proof of ability to pay damages: $10,000 for one person, $20,000 for two or more (bodily injury), plus property damage | D7: Ch. 324 (2022 text) | E7: Florida Statutes Chapter 324 - Financial Responsibility (2022 text) | F7: https://www.flsenate.gov/Laws/Statutes/2022/Chapter324/All | G7: 46295 | H7: Florida | I7: Statute / regulation text | J7: Primary source | K7: 46295 | L7: Confirm current text; SR-22 is the filing that certifies BIL and PDL after a suspension (FLHSMV).
A8: Financial responsibility | B8: DUI convictions | C8: BI liability of $100,000/$300,000 and $50,000 PD required | D8: s. 324.023 (per law-firm sources) | E8: Viles & Beckman - Did Florida repeal no-fault? (Jul 2026) | F8: https://www.vilesandbeckman.com/blog/did-florida-repeal-no-fault-insurance-the-pip-myths-and-the-facts-for-2026/ | G8: 46295 | H8: Florida | I8: Reference data (secondary source) | J8: Secondary - unverified | K8: 46295 | L8: Not confirmed from statute text.
A9: No-fault | B9: Serious-injury threshold, 14-day rule, 60% wage loss, $5,000 death benefit | C9: Reported by law firms; PIP requires treatment within 14 days; lawsuits for pain and suffering require a defined serious injury | D9: s. 627.736, 627.737 (per law-firm sources) | E9: Viles & Beckman - Did Florida repeal no-fault? (Jul 2026) | F9: https://www.vilesandbeckman.com/blog/did-florida-repeal-no-fault-insurance-the-pip-myths-and-the-facts-for-2026/ | G9: 46295 | H9: Florida | I9: Reference data (secondary source) | J9: Secondary - unverified | K9: 46295 | L9: Read the statute before publishing.
A10: Legislation | B10: PIP repeal | C10: SB 522 and HB 769 died in committee on Mar 13, 2026; PIP remains required | D10: Florida Legislature (per law-firm sources) | E10: Viles & Beckman - Did Florida repeal no-fault? (Jul 2026) | F10: https://www.vilesandbeckman.com/blog/did-florida-repeal-no-fault-insurance-the-pip-myths-and-the-facts-for-2026/ | G10: 46295 | H10: Florida | I10: Reference data (secondary source) | J10: Secondary - unverified | K10: 46295 | L10: Next session convenes Mar 2, 2027; verify at flsenate.gov.
A11: Policy changes | B11: Cancellation | C11: At least 45 days' notice (10 days for nonpayment); notice must explain appeal right to the Office of Insurance Regulation (appeal at least 20 days before effective date) | D11: s. 627.728 | E11: Florida Statutes 627.728 - Cancellations; nonrenewals (2025, via Justia) | F11: https://law.justia.com/codes/florida/title-xxxvii/chapter-627/part-xi/section-627-728/ | G11: 46295 | H11: Florida | I11: Statute / regulation text | J11: Primary source | K11: 46295 | L11: Nonrenewal rules for private passenger auto not captured; s. 626.9201 sits in the surplus lines part of the code.
A12: Rating | B12: Credit | C12: Statute regulates and limits use of credit reports and scores in personal lines motor vehicle and residential insurance; insurer must disclose the request and use DFS-prescribed language; certain inquiries and medical collections may not be used; appeal rights for events such as divorce, spouse's death, temporary job loss | D12: s. 626.9741 | E12: Florida Statutes 626.9741 - Credit reports and scores by insurers | F12: https://www.flsenate.gov/Laws/Statutes/2025/0626.9741 | G12: 46295 | H12: Florida | I12: Statute / regulation text | J12: Primary source | K12: 46295 | L12: Seen in snippets and older-year text; fetch was rate-limited. Confirm full text.
A13: Discounts | B13: Statutory discounts | C13: Sections 627.06501 (driver improvement course, discount up to 10% presumed appropriate), 627.0652 (safety course, 3-year reduction), 627.0653 (specified equipment) | D13: Fla. Stat. 627.06501, 627.0652, 627.0653 | E13: Florida Statutes Chapter 627 (2025) - table of contents | F13: https://www.flsenate.gov/Laws/Statutes/2025/Chapter627/All | G13: 46295 | H13: Florida | I13: Statute / regulation text | J13: Secondary - unverified | K13: 46295 | L13: Section titles confirmed in the 2025 table of contents; course text is from 2003 and 2012 versions.
A14: Rates | B14: Rate filing rules | C14: Section 627.0651 governs making and use of rates for motor vehicle insurance | D14: s. 627.0651 | E14: Florida Statutes Chapter 627 (2025) - table of contents | F14: https://www.flsenate.gov/Laws/Statutes/2025/Chapter627/All | G14: 46295 | H14: Florida | I14: Statute / regulation text | J14: Not researched | K14: 46295 | L14: Only the title was seen; not researched.

Sheet NY Auto Verified
A1: Topic | B1: Fact | C1: Value | D1: Legal Citation | E1: Source | F1: Source URL | G1: Date Collected | H1: Geographic Scope | I1: Data Type | J1: Verification Status | K1: Last Updated | L1: Notes
A2: Minimum liability | B2: Bodily injury | C2: $25,000 per person (non-death) or $50,000 (death); $50,000 for two or more (non-death) or $100,000 (death) | D2: NY Vehicle and Traffic Law (per DFS) | E2: NY Dept of Financial Services - Auto Insurance Information for Consumers | F2: https://www.dfs.ny.gov/consumers/auto_insurance/Auto_resource_center | G2: 46295 | H2: New York | I2: Regulator-published | J2: Primary source | K2: 46295
A3: Minimum liability | B3: Property damage | C3: $10,000 per accident (25/50/10) | D3: DFS | E3: NY Dept of Financial Services - Auto Insurance Information for Consumers | F3: https://www.dfs.ny.gov/consumers/auto_insurance/Auto_resource_center | G3: 46295 | H3: New York | I3: Regulator-published | J3: Primary source | K3: 46295
A4: No-fault | B4: Basic PIP | C4: $50,000 per person: medical, 80% of lost earnings up to $2,000 a month for up to 3 years, $25 a day for up to a year for other expenses, $2,000 death benefit | D4: DFS | E4: NY Dept of Financial Services - Auto Insurance Information for Consumers | F4: https://www.dfs.ny.gov/consumers/auto_insurance/Auto_resource_center | G4: 46295 | H4: New York | I4: Regulator-published | J4: Primary source | K4: 46295
A5: No-fault | B5: Lawsuits | C5: Non-economic damages only for a 'serious injury' as defined in the Insurance Law | D5: DFS | E5: NY Dept of Financial Services - Auto Insurance Information for Consumers | F5: https://www.dfs.ny.gov/consumers/auto_insurance/Auto_resource_center | G5: 46295 | H5: New York | I5: Regulator-published | J5: Primary source | K5: 46295
A6: No-fault | B6: Who is ineligible | C6: Impaired or intoxicated driver, intentional self-injury, ATV/motorcycle riders, felony, known stolen vehicle, owner of an uninsured vehicle | D6: DFS | E6: NY Dept of Financial Services - Auto Insurance Information for Consumers | F6: https://www.dfs.ny.gov/consumers/auto_insurance/Auto_resource_center | G6: 46295 | H6: New York | I6: Regulator-published | J6: Primary source | K6: 46295
